<robot name="abel_left_arm">

  <link name="base_link">
    <visual>
      <geometry>
        <box size="0.2 0.2 0.8" />
      </geometry>
      <material name="red">
        <color rgba="0 1 1 1" />
      </material>
    </visual>
    <collision>
      <geometry>
        <box size="0.2 0.2 0.8" />
      </geometry>
    </collision>
  </link>

  <joint name="joint_D6" type="revolute">
    <parent link="base_link"/>
    <child link="link_D6_D7"/>
    <origin xyz="-0.10 0 0" rpy="0 -1.57 0" />
    <axis xyz="0 0 1" />
    <limit effort="300" lower="-3.14" upper="0.261799" velocity="10"/>
    <safety_controller k_position="100" k_velocity="2" soft_lower_limit="-3.15" soft_upper_limit="0.27"/>
    <dynamics damping="0.5"/>
  </joint>

  <link name="link_D6_D7">
    <visual>
      <geometry>
        <cylinder length="0.1" radius="0.02"/>
      </geometry>
      <material name="blue">
        <color rgba="0 0 .8 1"/>
      </material>
    </visual>
    <collision>
      <geometry>
        <cylinder length="0.1" radius="0.02"/>
      </geometry>
    </collision>
  </link>

  <joint name="joint_D7" type="revolute">
    <parent link="link_D6_D7"/>
    <child link="link_D7_D8"/>
    <origin xyz="0 0 0.08" rpy="-1.57 -1.57 0" />
    <axis xyz="0 0 1" />
    <limit effort="300" lower="-0.0872665" upper="1.55" velocity="10"/>
    <safety_controller k_position="100" k_velocity="2" soft_lower_limit="-0.09" soft_upper_limit="1.57"/>
    <dynamics damping="0.5"/>
  </joint>

  <link name="link_D7_D8">
    <visual>
      <geometry>
        <cylinder length="0.02" radius="0.02"/>
      </geometry>
      <material name="blue">
        <color rgba="0 0 .8 1"/>
      </material>
    </visual>
    <collision>
      <geometry>
        <cylinder length="0.02" radius="0.02"/>
      </geometry>
    </collision>
  </link>

  <joint name="joint_D8" type="revolute">
    <parent link="link_D7_D8"/>
    <child link="link_D8_D9"/>
    <origin xyz="0 -0.095 0" rpy="-1.57 3.14 0" />
    <axis xyz="0 0 1" />
    <limit effort="300" lower="-1.25" upper="1" velocity="10"/>
    <safety_controller k_position="100" k_velocity="2" soft_lower_limit="-1.55" soft_upper_limit="1.1"/>
    <dynamics damping="0.5"/>
  </joint>

  <link name="link_D8_D9">
    <visual>
    <origin rpy="0 0 0" xyz="0 0 -0.015"/>
      <geometry>
        <cylinder length="0.175" radius="0.02"/>
      </geometry>
      <material name="blue">
        <color rgba="0 0 .8 1"/>
      </material>
    </visual>
    <collision>
    <origin rpy="0 0 0" xyz="0 0 -0.015"/>
      <geometry>
        <cylinder length="0.175" radius="0.02"/>
      </geometry>
    </collision>
  </link>

  <joint name="joint_D9" type="revolute">
    <parent link="link_D8_D9"/>
    <child link="link_D9_D10"/>
    <origin xyz="0 0 -0.125" rpy="0 -1.57 3.14" />
    <axis xyz="0 0 1" />
    <limit effort="300" lower="0" upper="2.26893" velocity="10"/>
    <safety_controller k_position="100" k_velocity="2" soft_lower_limit="-0.1" soft_upper_limit="2.27"/>
    <dynamics damping="0.5"/>
  </joint>

  <link name="link_D9_D10">
    <visual>
      <geometry>
        <cylinder length="0.06" radius="0.02"/>
      </geometry>
      <material name="blue">
        <color rgba="0 0 .8 1"/>
      </material>
    </visual>
    <collision>
      <geometry>
        <cylinder length="0.06" radius="0.02"/>
      </geometry>
    </collision>
  </link>

  <joint name="joint_D10" type="revolute">
    <parent link="link_D9_D10"/>
    <child link="link_D10_EE"/>
    <origin xyz="-0.065 0 0" rpy="3.14 -1.57 0" />
    <axis xyz="0 0 1" />
    <limit effort="300" lower="-1.48353" upper="0.523599" velocity="10"/>
    <safety_controller k_position="100" k_velocity="2" soft_lower_limit="-1.49" soft_upper_limit="0.53"/>
    <dynamics damping="0.5"/>
  </joint>

  <link name="link_D10_EE">
    <visual>
      <origin rpy="0 0 0" xyz="0 0 -0.125"/>
      <geometry>
        <cylinder length="0.325" radius="0.02"/>
      </geometry>
      <material name="blue">
        <color rgba="0 0 .8 1"/>
      </material>
    </visual>
    <collision>
    <origin rpy="0 0 0" xyz="0 0 -0.125"/>
      <geometry>
        <cylinder length="0.325" radius="0.02"/>
      </geometry>
    </collision>
  </link>

  <joint name="joint_EE_L" type="revolute">
    <parent link="link_D10_EE"/>
    <child link="link_EE_L"/>
    <origin xyz="0 0 -0.30" rpy="0 1.57 0" />
    <axis xyz="0 0 1" />
    <limit effort="300" lower="-2.09439510239" upper="2.09439510239" velocity="10"/>
    <safety_controller k_position="100" k_velocity="2" soft_lower_limit="-2.1" soft_upper_limit="2.1"/>
    <dynamics damping="0.5"/>
  </joint>

  <link name="link_EE_L">
    <visual>
      <geometry>
        <cylinder length="0.04" radius="0.03"/>
      </geometry>
      <material name="blue">
        <color rgba="0 0 .8 1"/>
      </material>
    </visual>
    <collision>
      <geometry>
        <cylinder length="0.06" radius="0.03"/>
      </geometry>
    </collision>
  </link>

  <!-- RIGHT ARM -->
  <joint name="joint_D11" type="revolute">
    <parent link="base_link"/>
    <child link="link_D11_D12"/>
    <origin xyz="0.10 0 0" rpy="0 -1.57 3.14" />
    <axis xyz="0 0 1" />
    <limit effort="300" lower="-0.26" upper="3.14" velocity="10"/>
    <safety_controller k_position="100" k_velocity="2" soft_lower_limit="-0.3" soft_upper_limit="3.15"/>
    <dynamics damping="0.5"/>
  </joint>

  <link name="link_D11_D12">
    <visual>
      <geometry>
        <cylinder length="0.1" radius="0.02"/>
      </geometry>
      <material name="blue">
        <color rgba="0 0 .8 1"/>
      </material>
    </visual>
    <collision>
      <geometry>
        <cylinder length="0.1" radius="0.02"/>
      </geometry>
    </collision>
  </link>

  <joint name="joint_D12" type="revolute">
    <parent link="link_D11_D12"/>
    <child link="link_D12_D13"/>
    <origin xyz="0 0 0.08" rpy="-1.57 -1.57 0" />
    <axis xyz="0 0 1" />
    <limit effort="300" lower="-0.0872665" upper="1.55" velocity="10"/>
    <safety_controller k_position="100" k_velocity="2" soft_lower_limit="-0.09" soft_upper_limit="1.57"/>
    <dynamics damping="0.5"/>
  </joint>

  <link name="link_D12_D13">
    <visual>
      <geometry>
        <cylinder length="0.02" radius="0.02"/>
      </geometry>
      <material name="blue">
        <color rgba="0 0 .8 1"/>
      </material>
    </visual>
    <collision>
      <geometry>
        <cylinder length="0.02" radius="0.02"/>
      </geometry>
    </collision>
  </link>

  <joint name="joint_D13" type="revolute">
    <parent link="link_D12_D13"/>
    <child link="link_D13_D14"/>
    <origin xyz="0 -0.095 0" rpy="-1.57 0 0" />
    <axis xyz="0 0 1" />
    <limit effort="300" lower="-1" upper="1.25" velocity="10"/>
    <safety_controller k_position="100" k_velocity="2" soft_lower_limit="-1.1" soft_upper_limit="1.55"/>
    <dynamics damping="0.5"/>
  </joint>

  <link name="link_D13_D14">
    <visual>
    <origin rpy="0 0 0" xyz="0 0 -0.015"/>
      <geometry>
        <cylinder length="0.175" radius="0.02"/>
      </geometry>
      <material name="blue">
        <color rgba="0 0 .8 1"/>
      </material>
    </visual>
    <collision>
    <origin rpy="0 0 0" xyz="0 0 -0.015"/>
      <geometry>
        <cylinder length="0.175" radius="0.02"/>
      </geometry>
    </collision>
  </link>

  <joint name="joint_D14" type="revolute">
    <parent link="link_D13_D14"/>
    <child link="link_D14_D15"/>
    <origin xyz="0 0 -0.125" rpy="0 -1.57 0" />
    <axis xyz="0 0 1" />
    <limit effort="300" lower="-2.26893" upper="0" velocity="10"/>
    <safety_controller k_position="100" k_velocity="2" soft_lower_limit="-2.27" soft_upper_limit="0.1"/>
    <dynamics damping="0.5"/>
  </joint>

  <link name="link_D14_D15">
    <visual>
      <geometry>
        <cylinder length="0.06" radius="0.02"/>
      </geometry>
      <material name="blue">
        <color rgba="0 0 .8 1"/>
      </material>
    </visual>
    <collision>
      <geometry>
        <cylinder length="0.06" radius="0.02"/>
      </geometry>
    </collision>
  </link>

  <joint name="joint_D15" type="revolute">
    <parent link="link_D14_D15"/>
    <child link="link_D15_EE"/>
    <origin xyz="-0.065 0 0" rpy="0 1.57 0" />
    <axis xyz="0 0 1" />
    <limit effort="300" lower="-1.48353" upper="0.523599" velocity="10"/>
    <safety_controller k_position="100" k_velocity="2" soft_lower_limit="-1.49" soft_upper_limit="0.53"/>
    <dynamics damping="0.5"/>
  </joint>

  <link name="link_D15_EE">
    <visual>
      <origin rpy="0 0 0" xyz="0 0 -0.125"/>
      <geometry>
        <cylinder length="0.325" radius="0.02"/>
      </geometry>
      <material name="blue">
        <color rgba="0 0 .8 1"/>
      </material>
    </visual>
    <collision>
    <origin rpy="0 0 0" xyz="0 0 -0.125"/>
      <geometry>
        <cylinder length="0.325" radius="0.05"/>
      </geometry>
    </collision>
  </link>

  <joint name="joint_EE" type="revolute">
    <parent link="link_D15_EE"/>
    <child link="link_EE_R"/>
    <origin xyz="0 0 -0.30" rpy="0 1.57 0" />
    <axis xyz="0 0 1" />
    <limit effort="300" lower="-2.09439510239" upper="2.09439510239" velocity="10"/>
    <safety_controller k_position="100" k_velocity="2" soft_lower_limit="-2.1" soft_upper_limit="2.1"/>
    <dynamics damping="0.5"/>
  </joint>

  <link name="link_EE_R">
    <visual>
      <geometry>
        <cylinder length="0.04" radius="0.03"/>
      </geometry>
      <material name="blue">
        <color rgba="0 0 .8 1"/>
      </material>
    </visual>
    <collision>
      <geometry>
        <cylinder length="0.04" radius="0.03"/>
      </geometry>
    </collision>
  </link>

</robot>
