<robot name="abel_left_arm">
  <link name="world" />

  <joint name="world_joint" type="fixed">
    <origin rpy="0 0 0" xyz="0 0 0"/>
    <parent link="world"/>
    <child link="link_0"/>
  </joint>

  <link name="link_0">
    <visual>
      <geometry>
        <box size="0.06 0.06 0.06"/>
      </geometry>
      <material name="blue">
        <color rgba="0 0 .8 1"/>
      </material>
    </visual>
    <collision>
      <geometry>
        <cylinder length="0.06" radius="0.02"/>
      </geometry>
    </collision>
  </link>

  <joint name="joint_0" type="continuous">
    <parent link="link_0"/>
    <child link="link_1"/>
    <origin xyz="-0.10 0 0" rpy="0 -1.57 0" />
    <axis xyz="0 0 1" />
    <limit effort="300" lower="-2.96705972839" upper="2.96705972839" velocity="10"/>
    <safety_controller k_position="100" k_velocity="2" soft_lower_limit="-2.93215314335" soft_upper_limit="2.93215314335"/>
    <dynamics damping="0.5"/>
  </joint>

  <link name="link_1">
    <visual>
      <geometry>
        <cylinder length="0.06" radius="0.02"/>
      </geometry>
      <material name="blue">
        <color rgba="0 0 .8 1"/>
      </material>
    </visual>
    <collision>
      <geometry>
        <cylinder length="0.06" radius="0.02"/>
      </geometry>
    </collision>
  </link>

  <joint name="joint_1" type="continuous">
    <parent link="link_1"/>
    <child link="link_2"/>
    <origin xyz="0 0 0.08" rpy="-1.57 -1.57 0" />
    <axis xyz="0 0 1" />
    <limit effort="300" lower="-2.09439510239" upper="2.09439510239" velocity="10"/>
    <safety_controller k_position="100" k_velocity="2" soft_lower_limit="-2.05948851735" soft_upper_limit="2.05948851735"/>
    <dynamics damping="0.5"/>
  </joint>

  <link name="link_2">
    <visual>
      <geometry>
        <cylinder length="0.06" radius="0.02"/>
      </geometry>
      <material name="blue">
        <color rgba="0 0 .8 1"/>
      </material>
    </visual>
    <collision>
      <geometry>
        <cylinder length="0.06" radius="0.02"/>
      </geometry>
    </collision>
  </link>

  <joint name="joint_2" type="continuous">
    <parent link="link_2"/>
    <child link="link_3"/>
    <origin xyz="0 -0.095 0" rpy="-1.57 3.14 0" />
    <axis xyz="0 0 1" />
    <limit effort="300" lower="-2.96705972839" upper="2.96705972839" velocity="10"/>
    <safety_controller k_position="100" k_velocity="2" soft_lower_limit="-2.93215314335" soft_upper_limit="2.93215314335"/>
    <dynamics damping="0.5"/>
  </joint>

  <link name="link_3">
    <visual>
      <geometry>
        <cylinder length="0.06" radius="0.02"/>
      </geometry>
      <material name="blue">
        <color rgba="0 0 .8 1"/>
      </material>
    </visual>
    <collision>
      <geometry>
        <cylinder length="0.06" radius="0.02"/>
      </geometry>
    </collision>
  </link>

  <joint name="joint_3" type="continuous">
    <parent link="link_3"/>
    <child link="link_4"/>
    <origin xyz="0 0 -0.125" rpy="0 -1.57 3.14" />
    <axis xyz="0 0 1" />
    <limit effort="300" lower="-2.09439510239" upper="2.09439510239" velocity="10"/>
    <safety_controller k_position="100" k_velocity="2" soft_lower_limit="-2.05948851735" soft_upper_limit="2.05948851735"/>
    <dynamics damping="0.5"/>
  </joint>

  <link name="link_4">
    <visual>
      <geometry>
        <cylinder length="0.06" radius="0.02"/>
      </geometry>
      <material name="blue">
        <color rgba="0 0 .8 1"/>
      </material>
    </visual>
    <collision>
      <geometry>
        <cylinder length="0.06" radius="0.02"/>
      </geometry>
    </collision>
  </link>

  <joint name="joint_4" type="continuous">
    <parent link="link_4"/>
    <child link="link_5"/>
    <origin xyz="-0.065 0 0" rpy="3.14 -1.57 0" />
    <axis xyz="0 0 1" />
    <limit effort="300" lower="-2.96705972839" upper="2.96705972839" velocity="10"/>
    <safety_controller k_position="100" k_velocity="2" soft_lower_limit="-2.93215314335" soft_upper_limit="2.93215314335"/>
    <dynamics damping="0.5"/>
  </joint>

  <link name="link_5">
    <visual>
      <geometry>
        <cylinder length="0.06" radius="0.02"/>
      </geometry>
      <material name="blue">
        <color rgba="0 0 .8 1"/>
      </material>
    </visual>
    <collision>
      <geometry>
        <cylinder length="0.06" radius="0.02"/>
      </geometry>
    </collision>
  </link>

  <joint name="joint_ee" type="continuous">
    <parent link="link_5"/>
    <child link="link_ee"/>
    <origin xyz="0 0 -0.30" rpy="0 0 0" />
    <limit effort="300" lower="-2.09439510239" upper="2.09439510239" velocity="10"/>
    <safety_controller k_position="100" k_velocity="2" soft_lower_limit="-2.05948851735" soft_upper_limit="2.05948851735"/>
    <dynamics damping="0.5"/>
  </joint>

  <link name="link_ee">
    <visual>
      <geometry>
        <cylinder length="0.06" radius="0.02"/>
      </geometry>
      <material name="blue">
        <color rgba="0 0 .8 1"/>
      </material>
    </visual>
    <collision>
      <geometry>
        <cylinder length="0.06" radius="0.02"/>
      </geometry>
    </collision>
  </link>

</robot>
