<robot name="abel_arms">
    <!-- LEFT ARM-->
    <link name="torso">
        <visual>
            <geometry>
                <box size="0.2 0.2 0.5" />
            </geometry>
            <material name="blue">
                <color rgba="0 0 .8 1" />
            </material>
        </visual>
        <collision>
            <geometry>
                <box size="0.2 0.2 0.5" />
            </geometry>
        </collision>
        
<inertial>
            <mass value="0.1" />
            <inertia ixx="0.03" iyy="0.03" izz="0.03" ixy="0.0" ixz="0.0" iyz="0.0" />
        </inertial>

    </link>
    <joint name="joint_0_l" type="continuous">
        <parent link="torso" />
        <child link="link_1_l" />
        <origin xyz="-0.10 0 0" rpy="0 -1.57 0" />
        <axis xyz="0 0 1" />
        <limit effort="300" lower="-2.96705972839" upper="2.96705972839" velocity="10" />
        <safety_controller k_position="100" k_velocity="2" soft_lower_limit="-2.93215314335" soft_upper_limit="2.93215314335" />
        <dynamics damping="0.5" />
    </joint>
    <link name="link_1_l">
        <visual>
            <geometry>
                <cylinder length="0.10" radius="0.03" />
            </geometry>
            <material name="blue">
                <color rgba="0 0 .8 1" />
            </material>
        </visual>
        <collision>
            <geometry>
                <cylinder length="0.10" radius="0.03" />
            </geometry>
        </collision>
        
<inertial>
            <mass value="0.1" />
            <inertia ixx="0.03" iyy="0.03" izz="0.03" ixy="0.0" ixz="0.0" iyz="0.0" />
        </inertial>

    </link>
    <joint name="joint_1_l" type="continuous">
        <parent link="link_1_l" />
        <child link="link_2_l" />
        <origin xyz="0 0 0.08" rpy="-1.57 -1.57 0" />
        <axis xyz="0 0 1" />
        <limit effort="300" lower="-2.09439510239" upper="2.09439510239" velocity="10" />
        <safety_controller k_position="100" k_velocity="2" soft_lower_limit="-2.05948851735" soft_upper_limit="2.05948851735" />
        <dynamics damping="0.5" />
    </joint>
    <link name="link_2_l">
        <visual>
            <geometry>
                <cylinder length="0.08" radius="0.03" />
            </geometry>
            <material name="blue">
                <color rgba="0 0 .8 1" />
            </material>
        </visual>
        <collision>
            <geometry>
                <cylinder length="0.08" radius="0.03" />
            </geometry>
        </collision>
        
<inertial>
            <mass value="0.1" />
            <inertia ixx="0.03" iyy="0.03" izz="0.03" ixy="0.0" ixz="0.0" iyz="0.0" />
        </inertial>

    </link>
    <joint name="joint_2_l" type="continuous">
        <parent link="link_2_l" />
        <child link="link_3_l" />
        <origin xyz="0 -0.095 0" rpy="-1.57 3.14 0" />
        <axis xyz="0 0 1" />
        <limit effort="300" lower="-2.96705972839" upper="2.96705972839" velocity="10" />
        <safety_controller k_position="100" k_velocity="2" soft_lower_limit="-2.93215314335" soft_upper_limit="2.93215314335" />
        <dynamics damping="0.5" />
    </joint>
    <link name="link_3_l">
        <visual>
            <geometry>
                <cylinder length="0.1" radius="0.025" />
            </geometry>
            <material name="blue">
                <color rgba="0 0 .8 1" />
            </material>
        </visual>
        <collision>
            <geometry>
                <cylinder length="0.1" radius="0.025" />
            </geometry>
        </collision>
        
<inertial>
            <mass value="0.1" />
            <inertia ixx="0.03" iyy="0.03" izz="0.03" ixy="0.0" ixz="0.0" iyz="0.0" />
        </inertial>

    </link>
    <joint name="joint_3_l" type="continuous">
        <parent link="link_3_l" />
        <child link="link_4_l" />
        <origin xyz="0 0 -0.125" rpy="0 -1.57 3.14" />
        <axis xyz="0 0 1" />
        <limit effort="300" lower="-2.09439510239" upper="2.09439510239" velocity="10" />
        <safety_controller k_position="100" k_velocity="2" soft_lower_limit="-2.05948851735" soft_upper_limit="2.05948851735" />
        <dynamics damping="0.5" />
    </joint>
    <link name="link_4_l">
        <visual>
            <geometry>
                <box size="0.05 0.03 0.03" />
            </geometry>
            <material name="blue">
                <color rgba="0 0 .8 1" />
            </material>
        </visual>
        <collision>
            <geometry>
                <box size="0.05 0.03 0.03" />
            </geometry>
        </collision>
        
<inertial>
            <mass value="0.1" />
            <inertia ixx="0.03" iyy="0.03" izz="0.03" ixy="0.0" ixz="0.0" iyz="0.0" />
        </inertial>

    </link>
    <joint name="joint_4_l" type="continuous">
        <parent link="link_4_l" />
        <child link="link_5_l" />
        <origin xyz="-0.065 0 0" rpy="3.14 -1.57 0" />
        <axis xyz="0 0 1" />
        <limit effort="300" lower="-2.96705972839" upper="2.96705972839" velocity="10" />
        <safety_controller k_position="100" k_velocity="2" soft_lower_limit="-2.93215314335" soft_upper_limit="2.93215314335" />
        <dynamics damping="0.5" />
    </joint>
    <link name="link_5_l">
        <visual>
            <geometry>
                <cylinder length="0.05" radius="0.02" />
            </geometry>
            <material name="blue">
                <color rgba="0 0 .8 1" />
            </material>
        </visual>
        <collision>
            <geometry>
                <cylinder length="0.06" radius="0.02" />
            </geometry>
        </collision>
        
<inertial>
            <mass value="0.1" />
            <inertia ixx="0.03" iyy="0.03" izz="0.03" ixy="0.0" ixz="0.0" iyz="0.0" />
        </inertial>

    </link>
    <joint name="joint_ee_l" type="continuous">
        <parent link="link_5_l" />
        <child link="link_ee_l" />
        <origin xyz="0 0 -0.30" rpy="0 0 0" />
        <limit effort="300" lower="-2.09439510239" upper="2.09439510239" velocity="10" />
        <safety_controller k_position="100" k_velocity="2" soft_lower_limit="-2.05948851735" soft_upper_limit="2.05948851735" />
        <dynamics damping="0.5" />
    </joint>
    <link name="link_ee_l">
        <visual>
            <geometry>
                <cylinder length="0.30" radius="0.02" />
            </geometry>
            <material name="blue">
                <color rgba="0 0 .8 1" />
            </material>
        </visual>
        <collision>
            <geometry>
                <cylinder length="0.30" radius="0.02" />
            </geometry>
        </collision>
        
<inertial>
            <mass value="0.1" />
            <inertia ixx="0.03" iyy="0.03" izz="0.03" ixy="0.0" ixz="0.0" iyz="0.0" />
        </inertial>

    </link>
    <!-- RIGHT ARM -->
    <joint name="joint_0_r" type="continuous">
        <parent link="torso" />
        <child link="link_1_r" />
        <origin xyz="0.10 0 0" rpy="0 -1.57 3.14" />
        <axis xyz="0 0 1" />
        <limit effort="300" lower="-2.96705972839" upper="2.96705972839" velocity="10" />
        <safety_controller k_position="100" k_velocity="2" soft_lower_limit="-2.93215314335" soft_upper_limit="2.93215314335" />
        <dynamics damping="0.5" />
    </joint>
    <link name="link_1_r">
        <visual>
            <geometry>
                <cylinder length="0.10" radius="0.03" />
            </geometry>
            <material name="blue">
                <color rgba="0 0 .8 1" />
            </material>
        </visual>
        <collision>
            <geometry>
                <cylinder length="0.10" radius="0.03" />
            </geometry>
        </collision>
        
<inertial>
            <mass value="0.1" />
            <inertia ixx="0.03" iyy="0.03" izz="0.03" ixy="0.0" ixz="0.0" iyz="0.0" />
        </inertial>

    </link>
    <joint name="joint_1_r" type="continuous">
        <parent link="link_1_r" />
        <child link="link_2_r" />
        <origin xyz="0 0 0.08" rpy="-1.57 -1.57 0" />
        <axis xyz="0 0 1" />
        <limit effort="300" lower="-2.09439510239" upper="2.09439510239" velocity="10" />
        <safety_controller k_position="100" k_velocity="2" soft_lower_limit="-2.05948851735" soft_upper_limit="2.05948851735" />
        <dynamics damping="0.5" />
    </joint>
    <link name="link_2_r">
        <visual>
            <geometry>
                <cylinder length="0.08" radius="0.03" />
            </geometry>
            <material name="blue">
                <color rgba="0 0 .8 1" />
            </material>
        </visual>
        <collision>
            <geometry>
                <cylinder length="0.08" radius="0.03" />
            </geometry>
        </collision>
        
<inertial>
            <mass value="0.1" />
            <inertia ixx="0.03" iyy="0.03" izz="0.03" ixy="0.0" ixz="0.0" iyz="0.0" />
        </inertial>

    </link>
    <joint name="joint_2_r" type="continuous">
        <parent link="link_2_r" />
        <child link="link_3_r" />
        <origin xyz="0 -0.095 0" rpy="-1.57 0 0" />
        <axis xyz="0 0 1" />
        <limit effort="300" lower="-2.96705972839" upper="2.96705972839" velocity="10" />
        <safety_controller k_position="100" k_velocity="2" soft_lower_limit="-2.93215314335" soft_upper_limit="2.93215314335" />
        <dynamics damping="0.5" />
    </joint>
    <link name="link_3_r">
        <visual>
            <geometry>
                <cylinder length="0.1" radius="0.025" />
            </geometry>
            <material name="blue">
                <color rgba="0 0 .8 1" />
            </material>
        </visual>
        <collision>
            <geometry>
                <cylinder length="0.1" radius="0.025" />
            </geometry>
        </collision>
        
<inertial>
            <mass value="0.1" />
            <inertia ixx="0.03" iyy="0.03" izz="0.03" ixy="0.0" ixz="0.0" iyz="0.0" />
        </inertial>

    </link>
    <joint name="joint_3_r" type="continuous">
        <parent link="link_3_r" />
        <child link="link_4_r" />
        <origin xyz="0 0 -0.125" rpy="0 -1.57 0" />
        <axis xyz="0 0 1" />
        <limit effort="300" lower="-2.09439510239" upper="2.09439510239" velocity="10" />
        <safety_controller k_position="100" k_velocity="2" soft_lower_limit="-2.05948851735" soft_upper_limit="2.05948851735" />
        <dynamics damping="0.5" />
    </joint>
    <link name="link_4_r">
        <visual>
            <geometry>
                <box size="0.05 0.03 0.03" />
            </geometry>
            <material name="blue">
                <color rgba="0 0 .8 1" />
            </material>
        </visual>
        <collision>
            <geometry>
                <box size="0.05 0.03 0.03" />
            </geometry>
        </collision>
        
<inertial>
            <mass value="0.1" />
            <inertia ixx="0.03" iyy="0.03" izz="0.03" ixy="0.0" ixz="0.0" iyz="0.0" />
        </inertial>

    </link>
    <joint name="joint_4_r" type="continuous">
        <parent link="link_4_r" />
        <child link="link_5_r" />
        <origin xyz="-0.065 0 0" rpy="0 1.57 0" />
        <axis xyz="0 0 1" />
        <limit effort="300" lower="-2.96705972839" upper="2.96705972839" velocity="10" />
        <safety_controller k_position="100" k_velocity="2" soft_lower_limit="-2.93215314335" soft_upper_limit="2.93215314335" />
        <dynamics damping="0.5" />
    </joint>
    <link name="link_5_r">
        <visual>
            <geometry>
                <cylinder length="0.05" radius="0.02" />
            </geometry>
            <material name="blue">
                <color rgba="0 0 .8 1" />
            </material>
        </visual>
        <collision>
            <geometry>
                <cylinder length="0.06" radius="0.02" />
            </geometry>
        </collision>
        
<inertial>
            <mass value="0.1" />
            <inertia ixx="0.03" iyy="0.03" izz="0.03" ixy="0.0" ixz="0.0" iyz="0.0" />
        </inertial>

    </link>
    <joint name="joint_ee_r" type="continuous">
        <parent link="link_5_r" />
        <child link="link_ee_r" />
        <origin xyz="0 0 -0.30" rpy="0 0 0" />
        <limit effort="300" lower="-2.09439510239" upper="2.09439510239" velocity="10" />
        <safety_controller k_position="100" k_velocity="2" soft_lower_limit="-2.05948851735" soft_upper_limit="2.05948851735" />
        <dynamics damping="0.5" />
    </joint>
    <link name="link_ee_r">
        <visual>
            <geometry>
                <cylinder length="0.30" radius="0.02" />
            </geometry>
            <material name="blue">
                <color rgba="0 0 .8 1" />
            </material>
        </visual>
        <collision>
            <geometry>
                <cylinder length="0.30" radius="0.02" />
            </geometry>
        </collision>
        
<inertial>
            <mass value="0.1" />
            <inertia ixx="0.03" iyy="0.03" izz="0.03" ixy="0.0" ixz="0.0" iyz="0.0" />
        </inertial>

    </link>
    
<transmission name="trans_joint_0_l">
        <type>transmission_interface/SimpleTransmission</type>
        <joint name="joint_0_l">
            <hardwareInterface>hardware_interface/EffortJointInterface</hardwareInterface>
        </joint>
        <actuator name="joint_0_l_motor">
            <hardwareInterface>hardware_interface/EffortJointInterface</hardwareInterface>
            <mechanicalReduction>1</mechanicalReduction>
        </actuator>
    </transmission>
    <transmission name="trans_joint_1_l">
        <type>transmission_interface/SimpleTransmission</type>
        <joint name="joint_1_l">
            <hardwareInterface>hardware_interface/EffortJointInterface</hardwareInterface>
        </joint>
        <actuator name="joint_1_l_motor">
            <hardwareInterface>hardware_interface/EffortJointInterface</hardwareInterface>
            <mechanicalReduction>1</mechanicalReduction>
        </actuator>
    </transmission>
    <transmission name="trans_joint_2_l">
        <type>transmission_interface/SimpleTransmission</type>
        <joint name="joint_2_l">
            <hardwareInterface>hardware_interface/EffortJointInterface</hardwareInterface>
        </joint>
        <actuator name="joint_2_l_motor">
            <hardwareInterface>hardware_interface/EffortJointInterface</hardwareInterface>
            <mechanicalReduction>1</mechanicalReduction>
        </actuator>
    </transmission>
    <transmission name="trans_joint_3_l">
        <type>transmission_interface/SimpleTransmission</type>
        <joint name="joint_3_l">
            <hardwareInterface>hardware_interface/EffortJointInterface</hardwareInterface>
        </joint>
        <actuator name="joint_3_l_motor">
            <hardwareInterface>hardware_interface/EffortJointInterface</hardwareInterface>
            <mechanicalReduction>1</mechanicalReduction>
        </actuator>
    </transmission>
    <transmission name="trans_joint_4_l">
        <type>transmission_interface/SimpleTransmission</type>
        <joint name="joint_4_l">
            <hardwareInterface>hardware_interface/EffortJointInterface</hardwareInterface>
        </joint>
        <actuator name="joint_4_l_motor">
            <hardwareInterface>hardware_interface/EffortJointInterface</hardwareInterface>
            <mechanicalReduction>1</mechanicalReduction>
        </actuator>
    </transmission>
    <transmission name="trans_joint_ee_l">
        <type>transmission_interface/SimpleTransmission</type>
        <joint name="joint_ee_l">
            <hardwareInterface>hardware_interface/EffortJointInterface</hardwareInterface>
        </joint>
        <actuator name="joint_ee_l_motor">
            <hardwareInterface>hardware_interface/EffortJointInterface</hardwareInterface>
            <mechanicalReduction>1</mechanicalReduction>
        </actuator>
    </transmission>
    <transmission name="trans_joint_0_r">
        <type>transmission_interface/SimpleTransmission</type>
        <joint name="joint_0_r">
            <hardwareInterface>hardware_interface/EffortJointInterface</hardwareInterface>
        </joint>
        <actuator name="joint_0_r_motor">
            <hardwareInterface>hardware_interface/EffortJointInterface</hardwareInterface>
            <mechanicalReduction>1</mechanicalReduction>
        </actuator>
    </transmission>
    <transmission name="trans_joint_1_r">
        <type>transmission_interface/SimpleTransmission</type>
        <joint name="joint_1_r">
            <hardwareInterface>hardware_interface/EffortJointInterface</hardwareInterface>
        </joint>
        <actuator name="joint_1_r_motor">
            <hardwareInterface>hardware_interface/EffortJointInterface</hardwareInterface>
            <mechanicalReduction>1</mechanicalReduction>
        </actuator>
    </transmission>
    <transmission name="trans_joint_2_r">
        <type>transmission_interface/SimpleTransmission</type>
        <joint name="joint_2_r">
            <hardwareInterface>hardware_interface/EffortJointInterface</hardwareInterface>
        </joint>
        <actuator name="joint_2_r_motor">
            <hardwareInterface>hardware_interface/EffortJointInterface</hardwareInterface>
            <mechanicalReduction>1</mechanicalReduction>
        </actuator>
    </transmission>
    <transmission name="trans_joint_3_r">
        <type>transmission_interface/SimpleTransmission</type>
        <joint name="joint_3_r">
            <hardwareInterface>hardware_interface/EffortJointInterface</hardwareInterface>
        </joint>
        <actuator name="joint_3_r_motor">
            <hardwareInterface>hardware_interface/EffortJointInterface</hardwareInterface>
            <mechanicalReduction>1</mechanicalReduction>
        </actuator>
    </transmission>
    <transmission name="trans_joint_4_r">
        <type>transmission_interface/SimpleTransmission</type>
        <joint name="joint_4_r">
            <hardwareInterface>hardware_interface/EffortJointInterface</hardwareInterface>
        </joint>
        <actuator name="joint_4_r_motor">
            <hardwareInterface>hardware_interface/EffortJointInterface</hardwareInterface>
            <mechanicalReduction>1</mechanicalReduction>
        </actuator>
    </transmission>
    <transmission name="trans_joint_ee_r">
        <type>transmission_interface/SimpleTransmission</type>
        <joint name="joint_ee_r">
            <hardwareInterface>hardware_interface/EffortJointInterface</hardwareInterface>
        </joint>
        <actuator name="joint_ee_r_motor">
            <hardwareInterface>hardware_interface/EffortJointInterface</hardwareInterface>
            <mechanicalReduction>1</mechanicalReduction>
        </actuator>
    </transmission>
    <gazebo>
        <plugin name="gazebo_ros_control" filename="libgazebo_ros_control.so">
            <robotNamespace>/</robotNamespace>
        </plugin>
    </gazebo>
    <transmission name="trans_joint_0_l">
        <type>transmission_interface/SimpleTransmission</type>
        <joint name="joint_0_l">
            <hardwareInterface>hardware_interface/EffortJointInterface</hardwareInterface>
        </joint>
        <actuator name="joint_0_l_motor">
            <hardwareInterface>hardware_interface/EffortJointInterface</hardwareInterface>
            <mechanicalReduction>1</mechanicalReduction>
        </actuator>
    </transmission>
    <transmission name="trans_joint_1_l">
        <type>transmission_interface/SimpleTransmission</type>
        <joint name="joint_1_l">
            <hardwareInterface>hardware_interface/EffortJointInterface</hardwareInterface>
        </joint>
        <actuator name="joint_1_l_motor">
            <hardwareInterface>hardware_interface/EffortJointInterface</hardwareInterface>
            <mechanicalReduction>1</mechanicalReduction>
        </actuator>
    </transmission>
    <transmission name="trans_joint_2_l">
        <type>transmission_interface/SimpleTransmission</type>
        <joint name="joint_2_l">
            <hardwareInterface>hardware_interface/EffortJointInterface</hardwareInterface>
        </joint>
        <actuator name="joint_2_l_motor">
            <hardwareInterface>hardware_interface/EffortJointInterface</hardwareInterface>
            <mechanicalReduction>1</mechanicalReduction>
        </actuator>
    </transmission>
    <transmission name="trans_joint_3_l">
        <type>transmission_interface/SimpleTransmission</type>
        <joint name="joint_3_l">
            <hardwareInterface>hardware_interface/EffortJointInterface</hardwareInterface>
        </joint>
        <actuator name="joint_3_l_motor">
            <hardwareInterface>hardware_interface/EffortJointInterface</hardwareInterface>
            <mechanicalReduction>1</mechanicalReduction>
        </actuator>
    </transmission>
    <transmission name="trans_joint_4_l">
        <type>transmission_interface/SimpleTransmission</type>
        <joint name="joint_4_l">
            <hardwareInterface>hardware_interface/EffortJointInterface</hardwareInterface>
        </joint>
        <actuator name="joint_4_l_motor">
            <hardwareInterface>hardware_interface/EffortJointInterface</hardwareInterface>
            <mechanicalReduction>1</mechanicalReduction>
        </actuator>
    </transmission>
    <transmission name="trans_joint_ee_l">
        <type>transmission_interface/SimpleTransmission</type>
        <joint name="joint_ee_l">
            <hardwareInterface>hardware_interface/EffortJointInterface</hardwareInterface>
        </joint>
        <actuator name="joint_ee_l_motor">
            <hardwareInterface>hardware_interface/EffortJointInterface</hardwareInterface>
            <mechanicalReduction>1</mechanicalReduction>
        </actuator>
    </transmission>
    <transmission name="trans_joint_0_r">
        <type>transmission_interface/SimpleTransmission</type>
        <joint name="joint_0_r">
            <hardwareInterface>hardware_interface/EffortJointInterface</hardwareInterface>
        </joint>
        <actuator name="joint_0_r_motor">
            <hardwareInterface>hardware_interface/EffortJointInterface</hardwareInterface>
            <mechanicalReduction>1</mechanicalReduction>
        </actuator>
    </transmission>
    <transmission name="trans_joint_1_r">
        <type>transmission_interface/SimpleTransmission</type>
        <joint name="joint_1_r">
            <hardwareInterface>hardware_interface/EffortJointInterface</hardwareInterface>
        </joint>
        <actuator name="joint_1_r_motor">
            <hardwareInterface>hardware_interface/EffortJointInterface</hardwareInterface>
            <mechanicalReduction>1</mechanicalReduction>
        </actuator>
    </transmission>
    <transmission name="trans_joint_2_r">
        <type>transmission_interface/SimpleTransmission</type>
        <joint name="joint_2_r">
            <hardwareInterface>hardware_interface/EffortJointInterface</hardwareInterface>
        </joint>
        <actuator name="joint_2_r_motor">
            <hardwareInterface>hardware_interface/EffortJointInterface</hardwareInterface>
            <mechanicalReduction>1</mechanicalReduction>
        </actuator>
    </transmission>
    <transmission name="trans_joint_3_r">
        <type>transmission_interface/SimpleTransmission</type>
        <joint name="joint_3_r">
            <hardwareInterface>hardware_interface/EffortJointInterface</hardwareInterface>
        </joint>
        <actuator name="joint_3_r_motor">
            <hardwareInterface>hardware_interface/EffortJointInterface</hardwareInterface>
            <mechanicalReduction>1</mechanicalReduction>
        </actuator>
    </transmission>
    <transmission name="trans_joint_4_r">
        <type>transmission_interface/SimpleTransmission</type>
        <joint name="joint_4_r">
            <hardwareInterface>hardware_interface/EffortJointInterface</hardwareInterface>
        </joint>
        <actuator name="joint_4_r_motor">
            <hardwareInterface>hardware_interface/EffortJointInterface</hardwareInterface>
            <mechanicalReduction>1</mechanicalReduction>
        </actuator>
    </transmission>
    <transmission name="trans_joint_ee_r">
        <type>transmission_interface/SimpleTransmission</type>
        <joint name="joint_ee_r">
            <hardwareInterface>hardware_interface/EffortJointInterface</hardwareInterface>
        </joint>
        <actuator name="joint_ee_r_motor">
            <hardwareInterface>hardware_interface/EffortJointInterface</hardwareInterface>
            <mechanicalReduction>1</mechanicalReduction>
        </actuator>
    </transmission>
    <gazebo>
        <plugin name="gazebo_ros_control" filename="libgazebo_ros_control.so">
            <robotNamespace>/</robotNamespace>
        </plugin>
    </gazebo>
</robot>
